Workbook

Sheet Final Design
A1: FINAL DESIGN – 33 kV substation grounding grid (30 × 30 m yard), CYMGRD 6.3 / IEEE Std 80
A3: Design description
A4: Grid | B4: 6 × 6 bare annealed Cu conductors, 70 mm² (9.44 mm), 6 m mesh, 0.5 m depth, 0–30 m
A5: Perimeter ring | B5: 32 × 32 m ring 1 m outside the fence (−1 to 31 m), 6 elements/side, tied to all 24 grid-line ends
A6: Ground rods | B6: 20 × 16 mm Cu-bonded steel, 9 m (3 × 3 m sections) on the ring – corners + every 6 m
A7: Joints | B7: Exothermic welds at all crossings, ties and rod connections
A8: Fence | B8: On the 30 × 30 m line, bonded to the grid; gate swings inward
A9: Surface layer | B9: 0.1 m wet crushed rock (2500 Ω·m), extended ≥1.5 m outside the fence
A10: Fault basis | B10: 13,110 A LG at B1 (33 kV), X/R 45, t = 0.5 s, split factor 0.276, decrement 1.134
A12: Safety verification
A13: Check | B13: Worst value (V) | C13: Limit (V) | D13: Margin | E13: Result | F13: Source
A14: Touch – inside the grid | B14: ='Sweep D'!I3 -> 666.36 | C14: ='Unit Rates'!$C$6 -> 806.59 | D14: =(C14-B14)/C14 -> 0.17385537 | E14: =IF(B14<=C14,"PASS","FAIL") -> PASS | F14: Profile (−1,−1)→(31,31)
A15: Touch – 1 m outside the fence | B15: ='Sweep D'!W3 -> 609.74 | C15: ='Unit Rates'!$C$6 -> 806.59 | D15: =(C15-B15)/C15 -> 0.24405212 | E15: =IF(B15<=C15,"PASS","FAIL") -> PASS | F15: Profile (−1,−1)→(31,−1)
A16: Step – everywhere (to 6 m outside) | B16: ='Sweep D'!J3 -> 149.07 | C16: ='Unit Rates'!$C$41 -> 2560.25 | D16: =(C16-B16)/C16 -> 0.94177522 | E16: =IF(B16<=C16,"PASS","FAIL") -> PASS | F16: Profile (−6,−6)→(36,36)
A17: Overall result | E17: =IF(COUNTIF(E14:E16,"PASS")=3,"PASS","FAIL") -> PASS
A18: Governing margin (lowest touch margin) | D18: =MIN(D14,D15) -> 0.17385537
A19: GPR (V) | B19: ='Sweep D'!H3 -> 2635.21
A20: Split factor used / max split factor before touch limit is reached | B20: ='Unit Rates'!$C$42 -> 0.275889 | C20: ='Unit Rates'!$C$42*'Unit Rates'!$C$6/MAX(B14,B15) -> 0.33394758 | F20: Touch scales linearly with grid current, so the design stays safe while Sf is below this value
A22: Cost (Bangladesh market, Sep-2026)
A23: Installed grid + ring + rods + joints (direct) | B23: ='Sweep D'!L3 -> 1541517.9
A24: TOTAL budget incl. crushed rock, tests, OH&P, contingency, VAT (BDT) | B24: ='Budget vs Benchmark'!B13 -> 3334519.8
A25: TOTAL budget (lakh BDT) | B25: ='Budget vs Benchmark'!B15 -> 33.345198
A26: TOTAL budget (USD) | B26: ='Budget vs Benchmark'!B14 -> 27131.976
A27: Grid-only budget incl. mark-ups (excl. crushed rock) | B27: ='Budget vs Benchmark'!B17 -> 2131620.4
A28: Typical earthing budget range – low | B28: ='Budget vs Benchmark'!B22 -> 500000
A29: Typical earthing budget range – high | B29: ='Budget vs Benchmark'!B23 -> 2000000
A30: Grid-only budget vs typical range | B30: ='Budget vs Benchmark'!B30 -> Above range
A31: Full budget vs typical range | B31: ='Budget vs Benchmark'!B28 -> Above range
A33: Why 6×6 + ring over the cheaper 5×5 + ring
A34: Item | B34: 6×6 + ring (FINAL) | C34: 5×5 + ring | D34: Difference
A35: Touch inside (V) | B35: ='Sweep D'!I3 -> 666.36 | C35: ='Sweep D'!I4 -> 722.395 | D35: =B35-C35 -> -56.035
A36: Touch margin inside | B36: ='Sweep D'!U3 -> 0.17385537 | C36: ='Sweep D'!U4 -> 0.10438389 | D36: =B36-C36 -> 0.069471479
A37: Touch at fence (V) | B37: ='Sweep D'!W3 -> 609.74 | C37: ='Sweep D'!W4 -> 612.575 | D37: =B37-C37 -> -2.835
A38: Max tolerable split factor | B38: ='Unit Rates'!$C$42*'Unit Rates'!$C$6/MAX('Sweep D'!I3,'Sweep D'!W3) -> 0.33394758 | C38: ='Unit Rates'!$C$42*'Unit Rates'!$C$6/MAX('Sweep D'!I4,'Sweep D'!W4) -> 0.30804381 | D38: =B38-C38 -> 0.025903768
A39: Total budget (BDT) | B39: ='Budget vs Benchmark'!B13 -> 3334519.8 | C39: ='Budget vs Benchmark'!C13 -> 3145598 | D39: =B39-C39 -> 188921.8
A41: Decision | B41: 6×6 + ring gives ~7 percentage points more touch margin inside the grid and tolerates a higher split factor, for about 6% (≈৳1.9 lakh) more total budget. Both perform alike at the fence (the ring governs there). Unverified inputs (soil model, split factor) justify the larger margin.
A43: Design history
A44: Stage | B44: Design | C44: Touch inside (V) | D44: Touch at fence (V) | E44: Outcome
A45: 1 – Parametric sweep | B45: 6×6, 20 rods × 9 m (best of sweeps A–C) | C45: ='Sweep A'!I5 -> 714.443 | D45: Not checked | E45: Passed inside; mesh/rod options ranked by cost
A46: 2 – Perimeter check | B46: Same, contour (−5,−5)→(35,35) | C46: ='Sweep A'!I5 -> 714.443 | D46: > 806.59 (contour) | E46: FAILED outside the fence → perimeter ring added
...

Sheet Sweep A
A1: #Run | B1: Grid spacing (X×Y) | C1: # Rods | D1: Rod length(m) | E1: Total conductor length (m) | F1: Total rod length (m) | G1: Ground Resistance (Ω) | H1: GPR (V) | I1: Touch (V) | J1: Step (V) | K1: Pass/Fail | L1: Est. material cost | M1: Conductors per direction (n) | N1: Conductor length (m) | O1: Rod length (m) | P1: Exothermic joints (n² + rods) | Q1: Rod couplers | R1: Conductor cost (BDT) | S1: Rod cost (BDT) – whole 3 m sections | T1: Joint cost (BDT) | U1: Touch margin vs limit | V1: Est. cost (USD)
A2: 1 | B2: 4x4 | C2: 20 | D2: 9 | E2: 2*4*30 | F2: 20*9 | G2: 0.670035 | H2: 2694 | I2: 887.516 | J2: 163.9 | K2: FAIL | L2: =R2+S2+T2 -> 977774.03 | M2: 4 | N2: =2*M2*'Unit Rates'!$C$5 -> 240 | O2: =C2*D2 -> 180 | P2: =M2^2+C2 -> 36 | Q2: =C2*(ROUNDUP(D2/'Unit Rates'!$C$17,0)-1) -> 40 | R2: =N2*('Unit Rates'!$C$13+'Unit Rates'!$C$14) -> 419774.03 | S2: =C2*ROUNDUP(D2/'Unit Rates'!$C$17,0)*'Unit Rates'!$C$16+O2*'Unit Rates'!$C$19+Q2*'Unit Rates'!$C$18 -> 486000 | T2: =P2*'Unit Rates'!$C$21 -> 72000 | U2: =('Unit Rates'!$C$6-I2)/'Unit Rates'!$C$6 -> -0.10033102 | V2: =L2/'Unit Rates'!$C$32 -> 7955.8506
A3: 2 | B3: 4x4 asymmetric | C3: 20 | D3: 9 | E3: 2*4*30 | F3: 20*9 | G3: - | H3: - | I3: 856.141 | J3: 152.5 | K3: FAIL | L3: =R3+S3+T3 -> 977774.03 | M3: 4 | N3: =2*M3*'Unit Rates'!$C$5 -> 240 | O3: =C3*D3 -> 180 | P3: =M3^2+C3 -> 36 | Q3: =C3*(ROUNDUP(D3/'Unit Rates'!$C$17,0)-1) -> 40 | R3: =N3*('Unit Rates'!$C$13+'Unit Rates'!$C$14) -> 419774.03 | S3: =C3*ROUNDUP(D3/'Unit Rates'!$C$17,0)*'Unit Rates'!$C$16+O3*'Unit Rates'!$C$19+Q3*'Unit Rates'!$C$18 -> 486000 | T3: =P3*'Unit Rates'!$C$21 -> 72000 | U3: =('Unit Rates'!$C$6-I3)/'Unit Rates'!$C$6 -> -0.061432698 | V3: =L3/'Unit Rates'!$C$32 -> 7955.8506
A4: 3 | B4: 5x5 | C4: 20 | D4: 9 | E4: 2*5*30 | F4: 20*9 | G4: 0.661857 | H4: 2685.03 | I4: 751.441 | J4: 128.89 | K4: PASS | L4: =R4+S4+T4 -> 1100717.5 | M4: 5 | N4: =2*M4*'Unit Rates'!$C$5 -> 300 | O4: =C4*D4 -> 180 | P4: =M4^2+C4 -> 45 | Q4: =C4*(ROUNDUP(D4/'Unit Rates'!$C$17,0)-1) -> 40 | R4: =N4*('Unit Rates'!$C$13+'Unit Rates'!$C$14) -> 524717.54 | S4: =C4*ROUNDUP(D4/'Unit Rates'!$C$17,0)*'Unit Rates'!$C$16+O4*'Unit Rates'!$C$19+Q4*'Unit Rates'!$C$18 -> 486000 | T4: =P4*'Unit Rates'!$C$21 -> 90000 | U4: =('Unit Rates'!$C$6-I4)/'Unit Rates'!$C$6 -> 0.068373027 | V4: =L4/'Unit Rates'!$C$32 -> 8956.2046
A5: 4 | B5: 6x6 | C5: 20 | D5: 9 | E5: 2*6*30 | F5: 20*9 | G5: 0.651835 | H5: 2673.81 | I5: 714.443 | J5: 111.88 | K5: PASS | L5: =R5+S5+T5 -> 1227661 | M5: 6 | N5: =2*M5*'Unit Rates'!$C$5 -> 360 | O5: =C5*D5 -> 180 | P5: =M5^2+C5 -> 56 | Q5: =C5*(ROUNDUP(D5/'Unit Rates'!$C$17,0)-1) -> 40 | R5: =N5*('Unit Rates'!$C$13+'Unit Rates'!$C$14) -> 629661.05 | S5: =C5*ROUNDUP(D5/'Unit Rates'!$C$17,0)*'Unit Rates'!$C$16+O5*'Unit Rates'!$C$19+Q5*'Unit Rates'!$C$18 -> 486000 | T5: =P5*'Unit Rates'!$C$21 -> 112000 | U5: =('Unit Rates'!$C$6-I5)/'Unit Rates'!$C$6 -> 0.11424268 | V5: =L5/'Unit Rates'!$C$32 -> 9989.1054
A6: 5 | B6: 8x8 | C6: 20 | D6: 9 | E6: 2*8*30 | F6: 20*9 | G6: 0.644129 | H6: 2665.02 | I6: 654.096 | J6: 99.48 | K6: PASS | L6: =R6+S6+T6 -> 1493548.1 | M6: 8 | N6: =2*M6*'Unit Rates'!$C$5 -> 480 | O6: =C6*D6 -> 180 | P6: =M6^2+C6 -> 84 | Q6: =C6*(ROUNDUP(D6/'Unit Rates'!$C$17,0)-1) -> 40 | R6: =N6*('Unit Rates'!$C$13+'Unit Rates'!$C$14) -> 839548.07 | S6: =C6*ROUNDUP(D6/'Unit Rates'!$C$17,0)*'Unit Rates'!$C$16+O6*'Unit Rates'!$C$19+Q6*'Unit Rates'!$C$18 -> 486000 | T6: =P6*'Unit Rates'!$C$21 -> 168000 | U6: =('Unit Rates'!$C$6-I6)/'Unit Rates'!$C$6 -> 0.18906012 | V6: =L6/'Unit Rates'!$C$32 -> 12152.547
A7: 6 | B7: 10x10 | C7: 20 | D7: 9 | E7: 2*10*30 | F7: 20*9 | G7: 0.641795 | H7: 2662.32 | I7: 634.313 | J7: 99.38 | K7: PASS | L7: =R7+S7+T7 -> 1775435.1 | M7: 10 | N7: =2*M7*'Unit Rates'!$C$5 -> 600 | O7: =C7*D7 -> 180 | P7: =M7^2+C7 -> 120 | Q7: =C7*(ROUNDUP(D7/'Unit Rates'!$C$17,0)-1) -> 40 | R7: =N7*('Unit Rates'!$C$13+'Unit Rates'!$C$14) -> 1049435.1 | S7: =C7*ROUNDUP(D7/'Unit Rates'!$C$17,0)*'Unit Rates'!$C$16+O7*'Unit Rates'!$C$19+Q7*'Unit Rates'!$C$18 -> 486000 | T7: =P7*'Unit Rates'!$C$21 -> 240000 | U7: =('Unit Rates'!$C$6-I7)/'Unit Rates'!$C$6 -> 0.21358683 | V7: =L7/'Unit Rates'!$C$32 -> 14446.176
A9: Cost columns L and M–V added: formulas use rates on the 'Unit Rates' sheet. Negative touch margin = design exceeds the tolerable touch voltage.

Sheet Sweep B
A1: #Run | B1: Grid spacing (X×Y) | C1: # Rods | D1: Rod length(m) | E1: Total conductor length (m) | F1: Total rod length (m) | G1: Ground Resistance (Ω) | H1: GPR (V) | I1: Touch (V) | J1: Step (V) | K1: Pass/Fail | L1: Est. material cost | M1: Conductors per direction (n) | N1: Conductor length (m) | O1: Rod length (m) | P1: Exothermic joints (n² + rods) | Q1: Rod couplers | R1: Conductor cost (BDT) | S1: Rod cost (BDT) – whole 3 m sections | T1: Joint cost (BDT) | U1: Touch margin vs limit | V1: Est. cost (USD)
A2: 1 | B2: 5x5 | C2: 20 | D2: 9 | E2: 2*5*30 | F2: 20*9 | G2: 0.661857 | H2: 2685.03 | I2: 751.441 | J2: 128.89 | K2: PASS | L2: =R2+S2+T2 -> 1100717.5 | M2: 5 | N2: =2*M2*'Unit Rates'!$C$5 -> 300 | O2: =C2*D2 -> 180 | P2: =M2^2+C2 -> 45 | Q2: =C2*(ROUNDUP(D2/'Unit Rates'!$C$17,0)-1) -> 40 | R2: =N2*('Unit Rates'!$C$13+'Unit Rates'!$C$14) -> 524717.54 | S2: =C2*ROUNDUP(D2/'Unit Rates'!$C$17,0)*'Unit Rates'!$C$16+O2*'Unit Rates'!$C$19+Q2*'Unit Rates'!$C$18 -> 486000 | T2: =P2*'Unit Rates'!$C$21 -> 90000 | U2: =('Unit Rates'!$C$6-I2)/'Unit Rates'!$C$6 -> 0.068373027 | V2: =L2/'Unit Rates'!$C$32 -> 8956.2046
A3: 2 | B3: 5x5 | C3: 16 | D3: 9 | E3: 2*5*30 | F3: 16*9 | G3: - | H3: - | I3: 836.451 | J3: 142.45 | K3: FAIL | L3: =R3+S3+T3 -> 995517.54 | M3: 5 | N3: =2*M3*'Unit Rates'!$C$5 -> 300 | O3: =C3*D3 -> 144 | P3: =M3^2+C3 -> 41 | Q3: =C3*(ROUNDUP(D3/'Unit Rates'!$C$17,0)-1) -> 32 | R3: =N3*('Unit Rates'!$C$13+'Unit Rates'!$C$14) -> 524717.54 | S3: =C3*ROUNDUP(D3/'Unit Rates'!$C$17,0)*'Unit Rates'!$C$16+O3*'Unit Rates'!$C$19+Q3*'Unit Rates'!$C$18 -> 388800 | T3: =P3*'Unit Rates'!$C$21 -> 82000 | U3: =('Unit Rates'!$C$6-I3)/'Unit Rates'!$C$6 -> -0.037021287 | V3: =L3/'Unit Rates'!$C$32 -> 8100.2241
A4: 3 | B4: 5x5 | C4: 24 | D4: 9 | E4: 2*5*30 | F4: 24*9 | G4: 0.634816 | H4: 2654.18 | I4: 706.932 | J4: 118.55 | K4: PASS | L4: =R4+S4+T4 -> 1205917.5 | M4: 5 | N4: =2*M4*'Unit Rates'!$C$5 -> 300 | O4: =C4*D4 -> 216 | P4: =M4^2+C4 -> 49 | Q4: =C4*(ROUNDUP(D4/'Unit Rates'!$C$17,0)-1) -> 48 | R4: =N4*('Unit Rates'!$C$13+'Unit Rates'!$C$14) -> 524717.54 | S4: =C4*ROUNDUP(D4/'Unit Rates'!$C$17,0)*'Unit Rates'!$C$16+O4*'Unit Rates'!$C$19+Q4*'Unit Rates'!$C$18 -> 583200 | T4: =P4*'Unit Rates'!$C$21 -> 98000 | U4: =('Unit Rates'!$C$6-I4)/'Unit Rates'!$C$6 -> 0.12355472 | V4: =L4/'Unit Rates'!$C$32 -> 9812.185
A6: Cost columns L and M–V added: formulas use rates on the 'Unit Rates' sheet. Negative touch margin = design exceeds the tolerable touch voltage.

Sheet Sweep c
A1: #Run | B1: Grid spacing (X×Y) | C1: # Rods | D1: Rod length(m) | E1: Total conductor length (m) | F1: Total rod length (m) | G1: Ground Resistance (Ω) | H1: GPR (V) | I1: Touch (V) | J1: Step (V) | K1: Pass/Fail | L1: Est. material cost | M1: Conductors per direction (n) | N1: Conductor length (m) | O1: Rod length (m) | P1: Exothermic joints (n² + rods) | Q1: Rod couplers | R1: Conductor cost (BDT) | S1: Rod cost (BDT) – whole 3 m sections | T1: Joint cost (BDT) | U1: Touch margin vs limit | V1: Est. cost (USD)
A2: 1 | B2: 5x5 | C2: 20 | D2: 9 | E2: 2*5*30 | F2: 20*9 | G2: 0.661857 | H2: 2685.03 | I2: 751.441 | J2: 128.89 | K2: PASS | L2: =R2+S2+T2 -> 1100717.5 | M2: 5 | N2: =2*M2*'Unit Rates'!$C$5 -> 300 | O2: =C2*D2 -> 180 | P2: =M2^2+C2 -> 45 | Q2: =C2*(ROUNDUP(D2/'Unit Rates'!$C$17,0)-1) -> 40 | R2: =N2*('Unit Rates'!$C$13+'Unit Rates'!$C$14) -> 524717.54 | S2: =C2*ROUNDUP(D2/'Unit Rates'!$C$17,0)*'Unit Rates'!$C$16+O2*'Unit Rates'!$C$19+Q2*'Unit Rates'!$C$18 -> 486000 | T2: =P2*'Unit Rates'!$C$21 -> 90000 | U2: =('Unit Rates'!$C$6-I2)/'Unit Rates'!$C$6 -> 0.068373027 | V2: =L2/'Unit Rates'!$C$32 -> 8956.2046
A3: 2 | B3: 5x5 | C3: 20 | D3: 8 | E3: 2*5*30 | F3: 20*8 | G3: 0.682767 | H3: 2707.65 | I3: 792.355 | J3: 139.39 | K3: PASS | L3: =R3+S3+T3 -> 1092717.5 | M3: 5 | N3: =2*M3*'Unit Rates'!$C$5 -> 300 | O3: =C3*D3 -> 160 | P3: =M3^2+C3 -> 45 | Q3: =C3*(ROUNDUP(D3/'Unit Rates'!$C$17,0)-1) -> 40 | R3: =N3*('Unit Rates'!$C$13+'Unit Rates'!$C$14) -> 524717.54 | S3: =C3*ROUNDUP(D3/'Unit Rates'!$C$17,0)*'Unit Rates'!$C$16+O3*'Unit Rates'!$C$19+Q3*'Unit Rates'!$C$18 -> 478000 | T3: =P3*'Unit Rates'!$C$21 -> 90000 | U3: =('Unit Rates'!$C$6-I3)/'Unit Rates'!$C$6 -> 0.017648372 | V3: =L3/'Unit Rates'!$C$32 -> 8891.111
A4: 3 | B4: 5x5 | C4: 20 | D4: 7 | E4: 2*5*30 | F4: 20*7 | G4: - | H4: - | I4: 839.528 | J4: 150.84 | K4: FAIL | L4: =R4+S4+T4 -> 1084717.5 | M4: 5 | N4: =2*M4*'Unit Rates'!$C$5 -> 300 | O4: =C4*D4 -> 140 | P4: =M4^2+C4 -> 45 | Q4: =C4*(ROUNDUP(D4/'Unit Rates'!$C$17,0)-1) -> 40 | R4: =N4*('Unit Rates'!$C$13+'Unit Rates'!$C$14) -> 524717.54 | S4: =C4*ROUNDUP(D4/'Unit Rates'!$C$17,0)*'Unit Rates'!$C$16+O4*'Unit Rates'!$C$19+Q4*'Unit Rates'!$C$18 -> 470000 | T4: =P4*'Unit Rates'!$C$21 -> 90000 | U4: =('Unit Rates'!$C$6-I4)/'Unit Rates'!$C$6 -> -0.040836113 | V4: =L4/'Unit Rates'!$C$32 -> 8826.0174
A6: Cost columns L and M–V added: formulas use rates on the 'Unit Rates' sheet. Negative touch margin = design exceeds the tolerable touch voltage.

Sheet Sweep D
A1: #Run | B1: Grid spacing (X×Y) | C1: # Rods | D1: Rod length(m) | E1: Total conductor length (m) | F1: Total rod length (m) | G1: Ground Resistance (Ω) | H1: GPR (V) | I1: Touch (V) | J1: Step (V) | K1: Pass/Fail | L1: Est. material cost | M1: Conductors per direction (n) | N1: Conductor length (m) | O1: Rod length (m) | P1: Exothermic joints (n² + rods + ties) | Q1: Rod couplers | R1: Conductor cost (BDT) | S1: Rod cost (BDT) – whole 3 m sections | T1: Joint cost (BDT) | U1: Touch margin vs limit | V1: Est. cost (USD) | W1: Touch at fence, 1 m outside (V) | X1: Fence touch margin | Y1: Ring elements per side | Z1: Status
A2: 1 | B2: 6x6 + ring | C2: 20 | D2: 9 | E2: grid 12×30 + ring 4×32 + 24 ties | F2: 20*9 | G2: - | H2: 2635.37 | I2: 669.213 | J2: 141.91 | K2: =IF(AND(I2<='Unit Rates'!$C$6,W2<='Unit Rates'!$C$6,J2<='Unit Rates'!$C$41),"PASS","FAIL") -> PASS | L2: =R2+S2+T2 -> 1541517.9 | M2: 6 | N2: =2*M2*'Unit Rates'!$C$5+4*('Unit Rates'!$C$5+2*'Unit Rates'!$C$40)+4*M2*'Unit Rates'!$C$40 -> 512 | O2: =C2*D2 -> 180 | P2: =M2^2+C2+4*M2 -> 80 | Q2: =C2*(ROUNDUP(D2/'Unit Rates'!$C$17,0)-1) -> 40 | R2: =N2*('Unit Rates'!$C$13+'Unit Rates'!$C$14) -> 895517.94 | S2: =C2*ROUNDUP(D2/'Unit Rates'!$C$17,0)*'Unit Rates'!$C$16+O2*'Unit Rates'!$C$19+Q2*'Unit Rates'!$C$18 -> 486000 | T2: =P2*'Unit Rates'!$C$21 -> 160000 | U2: =('Unit Rates'!$C$6-I2)/'Unit Rates'!$C$6 -> 0.17031825 | V2: =L2/'Unit Rates'!$C$32 -> 12542.864 | W2: 631.453 | X2: =('Unit Rates'!$C$6-W2)/'Unit Rates'!$C$6 -> 0.21713262 | Y2: 1 | Z2: Superseded – coarse ring model (1 element/side) overstated fence touch by ~22 V
A3: 2 | B3: 6x6 + ring | C3: 20 | D3: 9 | E3: grid 12×30 + ring 4×32 + 24 ties | F3: 20*9 | G3: - | H3: 2635.21 | I3: 666.36 | J3: 149.07 | K3: =IF(AND(I3<='Unit Rates'!$C$6,W3<='Unit Rates'!$C$6,J3<='Unit Rates'!$C$41),"PASS","FAIL") -> PASS | L3: =R3+S3+T3 -> 1541517.9 | M3: 6 | N3: =2*M3*'Unit Rates'!$C$5+4*('Unit Rates'!$C$5+2*'Unit Rates'!$C$40)+4*M3*'Unit Rates'!$C$40 -> 512 | O3: =C3*D3 -> 180 | P3: =M3^2+C3+4*M3 -> 80 | Q3: =C3*(ROUNDUP(D3/'Unit Rates'!$C$17,0)-1) -> 40 | R3: =N3*('Unit Rates'!$C$13+'Unit Rates'!$C$14) -> 895517.94 | S3: =C3*ROUNDUP(D3/'Unit Rates'!$C$17,0)*'Unit Rates'!$C$16+O3*'Unit Rates'!$C$19+Q3*'Unit Rates'!$C$18 -> 486000 | T3: =P3*'Unit Rates'!$C$21 -> 160000 | U3: =('Unit Rates'!$C$6-I3)/'Unit Rates'!$C$6 -> 0.17385537 | V3: =L3/'Unit Rates'!$C$32 -> 12542.864 | W3: 609.74 | X3: =('Unit Rates'!$C$6-W3)/'Unit Rates'!$C$6 -> 0.24405212 | Y3: 6 | Z3: FINAL DESIGN – selected
A4: 3 | B4: 5x5 + ring | C4: 20 | D4: 9 | E4: grid 10×30 + ring 4×32 + 20 ties | F4: 20*9 | G4: - | H4: 2640.08 | I4: 722.395 | J4: 151.21 | K4: =IF(AND(I4<='Unit Rates'!$C$6,W4<='Unit Rates'!$C$6,J4<='Unit Rates'!$C$41),"PASS","FAIL") -> PASS | L4: =R4+S4+T4 -> 1399578.2 | M4: 5 | N4: =2*M4*'Unit Rates'!$C$5+4*('Unit Rates'!$C$5+2*'Unit Rates'!$C$40)+4*M4*'Unit Rates'!$C$40 -> 448 | O4: =C4*D4 -> 180 | P4: =M4^2+C4+4*M4 -> 65 | Q4: =C4*(ROUNDUP(D4/'Unit Rates'!$C$17,0)-1) -> 40 | R4: =N4*('Unit Rates'!$C$13+'Unit Rates'!$C$14) -> 783578.19 | S4: =C4*ROUNDUP(D4/'Unit Rates'!$C$17,0)*'Unit Rates'!$C$16+O4*'Unit Rates'!$C$19+Q4*'Unit Rates'!$C$18 -> 486000 | T4: =P4*'Unit Rates'!$C$21 -> 130000 | U4: =('Unit Rates'!$C$6-I4)/'Unit Rates'!$C$6 -> 0.10438389 | V4: =L4/'Unit Rates'!$C$32 -> 11387.943 | W4: 612.575 | X4: =('Unit Rates'!$C$6-W4)/'Unit Rates'!$C$6 -> 0.24053732 | Y4: 6 | Z4: Meets IEEE 80 but only ~10% inside margin – rejected
A6: Stage 2 designs: 6×6 or 5×5 grid (0–30 m) + perimeter ring 32×32 m at 1 m outside the fence, tied to every grid line, 20 rods × 9 m moved onto the ring. Touch (col I) = profile (−1,−1)→(31,31); fence touch (col W) = profile (−1,−1)→(31,−1); step (col J) = max of all profiles incl. (−6,−6)→(36,36).
A7: Pass/Fail is now a formula: touch inside AND touch at fence ≤ 806.59 V, and step ≤ 2560.25 V. Ground resistance: see CYMGRD Grid analysis report (≈ GPR / grid current).

Sheet Unit Rates
A1: Bangladesh unit rates & design constants (edit blue cells; yellow = key assumptions)
A3: Item | C3: Value | D3: Unit | E3: Source / basis
A4: DESIGN CONSTANTS
A5: Grid side length (square yard) | C5: 30 | D5: m | E5: User design (CYMGRD grid 0–30 m)
A6: Max permissible touch voltage | C6: 806.59 | D6: V | E6: User CYMGRD Soil analysis report (70 kg, 0.5 s, 0.1 m wet crushed rock)
A7: Conductor cross-section | C7: 70 | D7: mm² | E7: User CYMGRD model: 9.44 mm solid Cu = 70 mm²
A8: GRID CONDUCTOR (bare annealed Cu)
A9: Copper density | C9: 8.89 | D9: g/cm³ | E9: Physical constant (annealed Cu)
A10: Conductor mass | C10: =C7*C9/1000 -> 0.6223 | D10: kg/m | E10: Formula: area × density
A11: Copper metal price (spot, in BDT) | C11: 1853 | D11: BDT/kg | E11: commoditypriceapi.com copper→BDT, 08-Sep-2026 (৳1,853/kg)
A12: Wire-drawing/stranding + dealer premium over metal | C12: 0.3 | D12: % | E12: Assumption: typical 25–40% for bare stranded earthing conductor; verify with BRB/Eastern/Superior Electric quote
A13: Conductor supply rate | C13: =C10*C11*(1+C12) -> 1499.0585 | D13: BDT/m | E13: Formula
A14: Trench 0.5–0.6 m, lay conductor, backfill & compact | C14: 250 | D14: BDT/m | E14: Assumption: local manual labour in kutcha ground; PWD SoR 2022 (2nd rev., Jan-2026) underground cable items imply ~৳200–300/m for trench+refill
A15: GROUND RODS (16 mm Cu-bonded steel, 3 m sections)
A16: Rod section price (16 mm × 3 m, threaded) | C16: 6500 | D16: BDT/each | E16: Estimate: Superior Electric (Mirpur) lists 12.7 mm × 3 m at ৳5,000 on BDStall; 16 mm scaled for ~1.6× steel mass
A17: Rod section length | C17: 3 | D17: m | E17: Standard section length
A18: Threaded coupler | C18: 600 | D18: BDT/each | E18: Assumption
A19: Rod driving labour (power hammer, alluvial soil) | C19: 400 | D19: BDT/m | E19: Assumption
A20: JOINTS
A21: Exothermic weld, all-in (cartridge + mould share + labour) | C21: 2000 | D21: BDT/joint | E21: Assumption: imported cartridge ≈ US$8–15 + graphite mould amortisation + labour; Indian brands (Amiable/AuraWeld) supply BD
A22: SURFACE LAYER & SITE WORKS (same for every grid option)
A23: Surface layer extension beyond grid edge (each side) | C23: 1.5 | D23: m | E23: Final design: crushed rock ≥1.5 m outside fence (fence on grid edge) so the 806.59 V limit applies in the 1 m reach zone
A24: Surface layer thickness | C24: 0.1 | D24: m | E24: User CYMGRD model
A25: Crushed stone (3/4") delivered | C25: 220 | D25: BDT/cft | E25: BDStall stone listings Sep-2026: ৳210–230/cft
A26: Spreading & levelling labour | C26: 15 | D26: BDT/cft | E26: Assumption
A27: Soil resistivity survey + fall-of-potential & continuity tests | C27: 60000 | D27: BDT lump | E27: Assumption
A28: MARK-UPS
A29: Contractor overhead & profit | C29: 0.1 | D29: % | E29: Assumption
A30: Contingency | C30: 0.1 | D30: % | E30: Assumption
A31: VAT | C31: 0.1 | D31: % | E31: PWD SoR 2022 (2nd revised, eff. 22-Jan-2026) applies VAT at 10%
A32: Exchange rate | C32: 122.9 | D32: BDT/USD | E32: Implied by commoditypriceapi.com (৳1,853/kg = US$15.08/kg), Sep-2026
A33: BENCHMARK (typical budget)
A34: 33/11 kV substation total cost – low | C34: 25000000 | D34: BDT | E34: AB Power Engineering (BD), Oct-2025: ৳2.5–4 crore for 3–10 MVA
A35: 33/11 kV substation total cost – high | C35: 40000000 | D35: BDT | E35: AB Power Engineering (BD), Oct-2025
A36: Earthing share of substation cost – low | C36: 0.02 | D36: % | E36: Assumption (rule of thumb) – replace with a BREB/PGCB BOQ if available
A37: Earthing share of substation cost – high | C37: 0.05 | D37: % | E37: Assumption (rule of thumb)
A39: STAGE 2 – PERIMETER RING & FINAL CHECKS
A40: Ring offset outside grid edge / fence | C40: 1 | D40: m | E40: User CYMGRD model: ring at −1 m and 31 m (fence on 0–30 m line)
A41: Max permissible step voltage | C41: 2560.25 | D41: V | E41: User CYMGRD Soil analysis report
A42: Current split factor used in CYMGRD | C42: 0.275889 | D42: – | E42: User CYMGRD Grid analysis report (2 lines, Rtg 15 Ω; 6 feeders, Rdg 25 Ω)
...

Sheet Design Comparison
A1: All unique designs from the sweeps – safety vs. installed grid cost
A3: Design | B3: Source | C3: Grid (n×n) | D3: Mesh spacing (m) | E3: # Rods | F3: Rod length (m) | G3: Touch (V) | H3: Step (V) | I3: Pass/Fail | J3: Touch margin | K3: Installed grid cost (BDT) | L3: Cost (USD) | M3: Cost rank among PASS (1 = cheapest) | N3: Extra cost vs cheapest PASS (BDT)
A4: 4×4, 20 rods × 9 m | B4: Sweep A, run 1 | C4: ='Sweep A'!M2 -> 4 | D4: ='Unit Rates'!$C$5/(C4-1) -> 10 | E4: ='Sweep A'!C2 -> 20 | F4: ='Sweep A'!D2 -> 9 | G4: ='Sweep A'!I2 -> 887.516 | H4: ='Sweep A'!J2 -> 163.9 | I4: ='Sweep A'!K2 -> FAIL | J4: ='Sweep A'!U2 -> -0.10033102 | K4: ='Sweep A'!L2 -> 977774.03 | L4: ='Sweep A'!V2 -> 7955.8506 | M4: =IF(I4="PASS",COUNTIFS($I$4:$I$13,"PASS",$K$4:$K$13,"<"&K4)+1,"–") -> – | N4: =IF(I4="PASS",K4-$K$15,"–") -> –
A5: 4×4 asymmetric, 20 rods × 9 m | B5: Sweep A, run 2 | C5: ='Sweep A'!M3 -> 4 | D5: ='Unit Rates'!$C$5/(C5-1) -> 10 | E5: ='Sweep A'!C3 -> 20 | F5: ='Sweep A'!D3 -> 9 | G5: ='Sweep A'!I3 -> 856.141 | H5: ='Sweep A'!J3 -> 152.5 | I5: ='Sweep A'!K3 -> FAIL | J5: ='Sweep A'!U3 -> -0.061432698 | K5: ='Sweep A'!L3 -> 977774.03 | L5: ='Sweep A'!V3 -> 7955.8506 | M5: =IF(I5="PASS",COUNTIFS($I$4:$I$13,"PASS",$K$4:$K$13,"<"&K5)+1,"–") -> – | N5: =IF(I5="PASS",K5-$K$15,"–") -> –
A6: 5×5, 20 rods × 9 m | B6: Sweep A, run 3 | C6: ='Sweep A'!M4 -> 5 | D6: ='Unit Rates'!$C$5/(C6-1) -> 7.5 | E6: ='Sweep A'!C4 -> 20 | F6: ='Sweep A'!D4 -> 9 | G6: ='Sweep A'!I4 -> 751.441 | H6: ='Sweep A'!J4 -> 128.89 | I6: ='Sweep A'!K4 -> PASS | J6: ='Sweep A'!U4 -> 0.068373027 | K6: ='Sweep A'!L4 -> 1100717.5 | L6: ='Sweep A'!V4 -> 8956.2046 | M6: =IF(I6="PASS",COUNTIFS($I$4:$I$13,"PASS",$K$4:$K$13,"<"&K6)+1,"–") -> 2 | N6: =IF(I6="PASS",K6-$K$15,"–") -> 8000
A7: 6×6, 20 rods × 9 m (Stage-1 best → final with ring, see Sweep D) | B7: Sweep A, run 4 | C7: ='Sweep A'!M5 -> 6 | D7: ='Unit Rates'!$C$5/(C7-1) -> 6 | E7: ='Sweep A'!C5 -> 20 | F7: ='Sweep A'!D5 -> 9 | G7: ='Sweep A'!I5 -> 714.443 | H7: ='Sweep A'!J5 -> 111.88 | I7: ='Sweep A'!K5 -> PASS | J7: ='Sweep A'!U5 -> 0.11424268 | K7: ='Sweep A'!L5 -> 1227661 | L7: ='Sweep A'!V5 -> 9989.1054 | M7: =IF(I7="PASS",COUNTIFS($I$4:$I$13,"PASS",$K$4:$K$13,"<"&K7)+1,"–") -> 4 | N7: =IF(I7="PASS",K7-$K$15,"–") -> 134943.51
A8: 8×8, 20 rods × 9 m | B8: Sweep A, run 5 | C8: ='Sweep A'!M6 -> 8 | D8: ='Unit Rates'!$C$5/(C8-1) -> 4.2857143 | E8: ='Sweep A'!C6 -> 20 | F8: ='Sweep A'!D6 -> 9 | G8: ='Sweep A'!I6 -> 654.096 | H8: ='Sweep A'!J6 -> 99.48 | I8: ='Sweep A'!K6 -> PASS | J8: ='Sweep A'!U6 -> 0.18906012 | K8: ='Sweep A'!L6 -> 1493548.1 | L8: ='Sweep A'!V6 -> 12152.547 | M8: =IF(I8="PASS",COUNTIFS($I$4:$I$13,"PASS",$K$4:$K$13,"<"&K8)+1,"–") -> 5 | N8: =IF(I8="PASS",K8-$K$15,"–") -> 400830.52
A9: 10×10, 20 rods × 9 m | B9: Sweep A, run 6 | C9: ='Sweep A'!M7 -> 10 | D9: ='Unit Rates'!$C$5/(C9-1) -> 3.3333333 | E9: ='Sweep A'!C7 -> 20 | F9: ='Sweep A'!D7 -> 9 | G9: ='Sweep A'!I7 -> 634.313 | H9: ='Sweep A'!J7 -> 99.38 | I9: ='Sweep A'!K7 -> PASS | J9: ='Sweep A'!U7 -> 0.21358683 | K9: ='Sweep A'!L7 -> 1775435.1 | L9: ='Sweep A'!V7 -> 14446.176 | M9: =IF(I9="PASS",COUNTIFS($I$4:$I$13,"PASS",$K$4:$K$13,"<"&K9)+1,"–") -> 6 | N9: =IF(I9="PASS",K9-$K$15,"–") -> 682717.54
A10: 5×5, 16 rods × 9 m | B10: Sweep B, run 2 | C10: ='Sweep B'!M3 -> 5 | D10: ='Unit Rates'!$C$5/(C10-1) -> 7.5 | E10: ='Sweep B'!C3 -> 16 | F10: ='Sweep B'!D3 -> 9 | G10: ='Sweep B'!I3 -> 836.451 | H10: ='Sweep B'!J3 -> 142.45 | I10: ='Sweep B'!K3 -> FAIL | J10: ='Sweep B'!U3 -> -0.037021287 | K10: ='Sweep B'!L3 -> 995517.54 | L10: ='Sweep B'!V3 -> 8100.2241 | M10: =IF(I10="PASS",COUNTIFS($I$4:$I$13,"PASS",$K$4:$K$13,"<"&K10)+1,"–") -> – | N10: =IF(I10="PASS",K10-$K$15,"–") -> –
A11: 5×5, 24 rods × 9 m | B11: Sweep B, run 3 | C11: ='Sweep B'!M4 -> 5 | D11: ='Unit Rates'!$C$5/(C11-1) -> 7.5 | E11: ='Sweep B'!C4 -> 24 | F11: ='Sweep B'!D4 -> 9 | G11: ='Sweep B'!I4 -> 706.932 | H11: ='Sweep B'!J4 -> 118.55 | I11: ='Sweep B'!K4 -> PASS | J11: ='Sweep B'!U4 -> 0.12355472 | K11: ='Sweep B'!L4 -> 1205917.5 | L11: ='Sweep B'!V4 -> 9812.185 | M11: =IF(I11="PASS",COUNTIFS($I$4:$I$13,"PASS",$K$4:$K$13,"<"&K11)+1,"–") -> 3 | N11: =IF(I11="PASS",K11-$K$15,"–") -> 113200
A12: 5×5, 20 rods × 8 m | B12: Sweep c, run 2 | C12: ='Sweep c'!M3 -> 5 | D12: ='Unit Rates'!$C$5/(C12-1) -> 7.5 | E12: ='Sweep c'!C3 -> 20 | F12: ='Sweep c'!D3 -> 8 | G12: ='Sweep c'!I3 -> 792.355 | H12: ='Sweep c'!J3 -> 139.39 | I12: ='Sweep c'!K3 -> PASS | J12: ='Sweep c'!U3 -> 0.017648372 | K12: ='Sweep c'!L3 -> 1092717.5 | L12: ='Sweep c'!V3 -> 8891.111 | M12: =IF(I12="PASS",COUNTIFS($I$4:$I$13,"PASS",$K$4:$K$13,"<"&K12)+1,"–") -> 1 | N12: =IF(I12="PASS",K12-$K$15,"–") -> 0
A13: 5×5, 20 rods × 7 m | B13: Sweep c, run 3 | C13: ='Sweep c'!M4 -> 5 | D13: ='Unit Rates'!$C$5/(C13-1) -> 7.5 | E13: ='Sweep c'!C4 -> 20 | F13: ='Sweep c'!D4 -> 7 | G13: ='Sweep c'!I4 -> 839.528 | H13: ='Sweep c'!J4 -> 150.84 | I13: ='Sweep c'!K4 -> FAIL | J13: ='Sweep c'!U4 -> -0.040836113 | K13: ='Sweep c'!L4 -> 1084717.5 | L13: ='Sweep c'!V4 -> 8826.0174 | M13: =IF(I13="PASS",COUNTIFS($I$4:$I$13,"PASS",$K$4:$K$13,"<"&K13)+1,"–") -> – | N13: =IF(I13="PASS",K13-$K$15,"–") -> –
J15: Cheapest PASS cost: | K15: =_xlfn.MINIFS(K4:K13,I4:I13,"PASS") -> 1092717.5
A17: Installed grid cost = conductor (supply + trench) + rods (sections + couplers + driving) + exothermic joints. Surface layer, testing, mark-ups & VAT are identical for all options and are handled on 'Budget vs Benchmark'.
A18: Touch margin = (806.59 V − touch) / 806.59 V. Aim for ≥10% margin given uncertainty in split factor and soil model.
A19: Bold row = current/recommended design. Cost ranking changes automatically if you edit the unit rates.
A20: Stage-1 sweep only checked touch inside the grid. Perimeter/fence check and the final ring designs are on 'Sweep D' and 'Final Design'.

Sheet Budget vs Benchmark
A1: Project budget for the grounding system vs. typical budget (BDT) – FINAL DESIGN
A3: Line item | B3: FINAL: 6×6 + ring, 20 rods × 9 m | C3: Alternative: 5×5 + ring, 20 rods × 9 m | D3: Basis
A4: Grid conductor – supply + trench/lay | B4: ='Sweep D'!R3 -> 895517.94 | C4: ='Sweep D'!R4 -> 783578.19 | D4: Sweep D col R (grid + ring + ties)
A5: Ground rods – sections, couplers, driving | B5: ='Sweep D'!S3 -> 486000 | C5: ='Sweep D'!S4 -> 486000 | D5: Sweep sheets col S
A6: Exothermic joints | B6: ='Sweep D'!T3 -> 160000 | C6: ='Sweep D'!T4 -> 130000 | D6: Sweep D col T (grid crossings + rod welds + tie welds)
A7: Surface layer – crushed stone supply + spreading | B7: =(('Unit Rates'!$C$5+2*'Unit Rates'!$C$23)^2*'Unit Rates'!$C$24*35.3147)*('Unit Rates'!$C$25+'Unit Rates'!$C$26) -> 903756.15 | C7: =(('Unit Rates'!$C$5+2*'Unit Rates'!$C$23)^2*'Unit Rates'!$C$24*35.3147)*('Unit Rates'!$C$25+'Unit Rates'!$C$26) -> 903756.15 | D7: (side + 2×ext)² × thickness, ×35.3147 cft/m³
A8: Soil survey & commissioning tests | B8: ='Unit Rates'!$C$27 -> 60000 | C8: ='Unit Rates'!$C$27 -> 60000 | D8: Lump sum
A9: Direct cost subtotal | B9: =SUM(B4:B8) -> 2505274.1 | C9: =SUM(C4:C8) -> 2363334.3 | D9: Sum
A10: Contractor overhead & profit | B10: =B9*'Unit Rates'!$C$29 -> 250527.41 | C10: =C9*'Unit Rates'!$C$29 -> 236333.43 | D10: × OH&P
A11: Contingency | B11: =(B9+B10)*'Unit Rates'!$C$30 -> 275580.15 | C11: =(C9+C10)*'Unit Rates'!$C$30 -> 259966.78 | D11: × contingency
A12: VAT | B12: =(B9+B10+B11)*'Unit Rates'!$C$31 -> 303138.16 | C12: =(C9+C10+C11)*'Unit Rates'!$C$31 -> 285963.46 | D12: × VAT
A13: TOTAL grounding system budget (BDT) | B13: =B9+B10+B11+B12 -> 3334519.8 | C13: =C9+C10+C11+C12 -> 3145598
A14: TOTAL (USD) | B14: =B13/'Unit Rates'!$C$32 -> 27131.976 | C14: =C13/'Unit Rates'!$C$32 -> 25594.776
A15: TOTAL (lakh BDT) | B15: =B13/100000 -> 33.345198 | C15: =C13/100000 -> 31.45598
A17: Grid-only total incl. mark-ups & VAT (excl. surface layer) | B17: =(SUM(B4:B6)+B8)*(1+'Unit Rates'!$C$29)*(1+'Unit Rates'!$C$30)*(1+'Unit Rates'!$C$31) -> 2131620.4 | C17: =(SUM(C4:C6)+C8)*(1+'Unit Rates'!$C$29)*(1+'Unit Rates'!$C$30)*(1+'Unit Rates'!$C$31) -> 1942698.6 | D17: Crushed rock is often costed under civil/yard works – this line isolates the electrical earthing scope
A19: BENCHMARK – typical budget
A20: Typical 33/11 kV substation cost – low | B20: ='Unit Rates'!$C$34 -> 25000000 | D20: AB Power Engineering (BD)
A21: Typical 33/11 kV substation cost – high | B21: ='Unit Rates'!$C$35 -> 40000000 | D21: AB Power Engineering (BD)
A22: Typical earthing budget – low (low cost × low share) | B22: ='Unit Rates'!$C$34*'Unit Rates'!$C$36 -> 500000 | D22: Rule-of-thumb share (Unit Rates)
A23: Typical earthing budget – high (high cost × high share) | B23: ='Unit Rates'!$C$35*'Unit Rates'!$C$37 -> 2000000 | D23: Rule-of-thumb share (Unit Rates)
A24: Typical earthing budget – mid-point | B24: =AVERAGE(B22,B23) -> 1250000 | D24: Average of low & high
A26: COMPARISON
A27: Full budget vs typical mid-point | B27: =B13/$B$24-1 -> 1.6676158 | C27: =C13/$B$24-1 -> 1.5164784
A28: Full budget within typical range? | B28: =IF(AND(B13>=$B$22,B13<=$B$23),"Within range",IF(B13<$B$22,"Below range","Above range")) -> Above range | C28: =IF(AND(C13>=$B$22,C13<=$B$23),"Within range",IF(C13<$B$22,"Below range","Above range")) -> Above range
A29: Grid-only vs typical mid-point | B29: =B17/$B$24-1 -> 0.7052963 | C29: =C17/$B$24-1 -> 0.55415886
A30: Grid-only within typical range? | B30: =IF(AND(B17>=$B$22,B17<=$B$23),"Within range",IF(B17<$B$22,"Below range","Above range")) -> Above range | C30: =IF(AND(C17>=$B$22,C17<=$B$23),"Within range",IF(C17<$B$22,"Below range","Above range")) -> Within range
A31: Full budget as % of mid-range substation cost | B31: =B13/AVERAGE('Unit Rates'!$C$34,'Unit Rates'!$C$35) -> 0.10260061 | C31: =C13/AVERAGE('Unit Rates'!$C$34,'Unit Rates'!$C$35) -> 0.096787631
A34: Benchmark method: typical 33/11 kV substation cost (published BD range) × assumed earthing share (2–5%). No public BD average exists for a 30×30 m grid, so treat this as an order-of-magnitude check and replace with a BREB/PGCB tender BOQ if you can obtain one.
A35: All rates are editable on 'Unit Rates'. Yellow cells are the ones most worth confirming with a local supplier quotation (copper conductor, rods, exothermic welds).
